<?xml version="1.0" encoding="utf-8"?>
<mujoco model="planar_gripper">
	<compiler angle="radian" coordinate="local" inertiafromgeom="true"/>
	<option integrator="RK4" timestep="0.01"/>
	<custom>
        <numeric name="init_qpos" data="0. 0.5 -0.6 0. -0.5 0.6"/>
	</custom>
	<default class="geom0">
		<joint armature="1" damping="1" limited="true" axis="0 1 0"/>
		<geom conaffinity="1" contype="1" condim="3" density="5.0" friction="1 0.5 0.5" margin="0.001" rgba="0.8 0.6 0.4 1"/>
	</default>
    <default class="geom1">
		<joint armature="1" damping="1" limited="true" axis="0 1 0"/>
		<geom conaffinity="1" contype="1" condim="3" density="10000.0" rgba="0.8 0.6 0.4 1"/>
	</default>
    <default class="geomroot">
		<geom conaffinity="1" contype="1" condim="3" density="5.0" friction="1 0.5 0.5" margin="0.001" rgba="0.8 0.6 0.4 1"/>
	</default>
	<asset>
		<texture builtin="gradient" height="100" rgb1="1 1 1" rgb2="0 0 0" type="skybox" width="100"/>
		<texture builtin="flat" height="1278" mark="cross" markrgb="1 1 1" name="texgeom" random="0.01" rgb1="0.8 0.6 0.4" rgb2="0.8 0.6 0.4" type="cube" width="127"/>
		<texture builtin="checker" height="100" name="texplane" rgb1="0 0 0" rgb2="0.8 0.8 0.8" type="2d" width="100"/>
		<material name="MatPlane" reflectance="0.5" shininess="1" specular="1" texrepeat="60 60" texture="texplane"/>
		<material name="geom" texture="texgeom" texuniform="true" rgba="1 1 1 1"/>
        <mesh name="Cylinder" file="cylinder.stl"/>
        <mesh name="OctPrism" file="octprism.stl"/>
        <mesh name="Ellipsoid" file="ellipsoid.stl"/>
        <mesh name="CapsuleShort" file="capsule.stl"/>
        <mesh name="CapsuleLong" file="capsule-2.stl"/>
	</asset>
	<worldbody>
		<light cutoff="100" diffuse="1 1 1" dir="0 0 -1.3" directional="true" exponent="1" pos="0 0 1.3" specular="0.1 0.1 0.1"/>
		<geom class="geom1" conaffinity="1" condim="3" material="MatPlane" name="floor" pos="0 0 0" rgba="0.8 0.9 0.8 1" size="40 40 40" type="plane"/>
		<body name="root" pos="0. 0. 0.">
			<camera mode="trackcom" name="track" pos="0 -3 0.3" xyaxes="1 0 0 0 0 1"/>
            <!-- Model base, raised by 0.15 due to root body transform being origin by default in Warp -->
			<geom name="root_geom" pos="0 0.15 0" size="0.1" type="sphere" class="geomroot"/>
            <joint axis="0 1 0" armature="0" damping="0" limited="true" margin="0.01" name="root" pos="0 0 0" type="hinge" range="-.1 .1"/>
			<body name="left_finger" pos="0.1 0.15 0.15" euler="0 0 90">
				<joint name="aux_joint_left_finger" range="-1 1" type="hinge" axis="0 0 1"/>
                <geom name="aux_geom_left_finger" size="0.001" type="sphere"/>
				<body name="proximal_body_left_finger" pos="0. -0.1 0." euler="0 0 0">
					<joint axis="1 0 0" name="proximal_joint_left_finger" pos="0.0 0.0 0.0" range="-90 0" type="hinge"/>
                    <geom class="geom0" name="proximal_geom_left_finger" size="1 1 1" type="mesh" mesh="CapsuleLong" contype="1" conaffinity="0"/>
					<body name="distal_body_left_finger" pos="0 -0.45 -0.11" euler="0 0 0">
						<joint axis="1 0 0" name="distal_joint_left_finger" range="0 60" type="hinge"/>
						<geom class="geom0" name="distal_geom_left_finger" size="1 1 1" type="mesh" mesh="CapsuleLong" contype="1" conaffinity="0"/>
					</body>
				</body>
			</body>
			<body name="right_finger" pos="0.1 0.15 -0.15" euler="0 0 90">
				<joint name="aux_joint_right_finger" range="-1 1" type="hinge" axis="0 0 1"/>
				<geom name="aux_geom_right_finger" size="0.001" type="sphere"/>
				<body name="proximal_body_right_finger" pos="0. -0.1 0." euler="0 0 0">
					<joint axis="0 1 0" name="proximal_joint_right_finger" pos="-0.2 0.0 0." range="0 90" type="hinge"/>
					<geom class="geom0" name="proximal_geom_right_finger" size="1 1 1" type="mesh" mesh="CapsuleLong" contype="1" conaffinity="0"/>
					<body name="distal_body_right_finger" pos="0. -0.45 0.1" euler="0 0 0">
						<joint axis="0 1 0" name="distal_joint_right_finger" pos="0.0 0.0 0.0" range="-60 0" type="hinge"/>
						<geom class="geom0" name="distal_geom_right_finger" size="1 1 1" type="mesh" mesh="CapsuleLong" contype="1" conaffinity="0"/>
					</body>
				</body>
			</body>
            <body name="object" pos="0.9 0.15 0." >
              <geom class="geom0" name="obj_com" rgba="1 1 1 0" type="sphere" size="0.1" contype="1" conaffinity="0"/>
              <geom class="geom0" name="obj_surface" rgba="1 1 1 1" type="mesh" mesh="OctPrism" size="2.5 2.5 2.5" contype="1" conaffinity="0"/>
              <joint name="obj_theta" type="hinge" pos="0 0 0" axis="0 1 0" range="-1 1" damping="0.5"/>
            </body>
		</body>

	</worldbody>
	<actuator>
		<motor ctrllimited="true" ctrlrange="-1.0 1.0" gear="150" joint="proximal_joint_left_finger"/>
		<motor ctrllimited="true" ctrlrange="-1.0 1.0" gear="150" joint="distal_joint_left_finger"/>
		<motor ctrllimited="true" ctrlrange="-1.0 1.0" gear="150" joint="proximal_joint_right_finger"/>
		<motor ctrllimited="true" ctrlrange="-1.0 1.0" gear="150" joint="distal_joint_right_finger"/>
	</actuator>
</mujoco>
