<?xml version="1.0" ?>
<robot name="partnet_8c34afa29665356013b1d3e1528f0506-0">
	<link name="base"/>
	<link name="link_0">
		<visual name="body-1">
			<origin xyz="-0.0 -0.09713288304940276 0.49444914751130464"/>
			<geometry>
				<mesh filename="textured_objs/original-2.obj"/>
			</geometry>
		</visual>
		<visual name="body-1">
			<origin xyz="-0.0 -0.09713288304940276 0.49444914751130464"/>
			<geometry>
				<mesh filename="textured_objs/original-3.obj"/>
			</geometry>
		</visual>
		<collision>
			<origin xyz="-0.0 -0.09713288304940276 0.49444914751130464"/>
			<geometry>
				<mesh filename="textured_objs/original-2.obj"/>
			</geometry>
		</collision>
		<collision>
			<origin xyz="-0.0 -0.09713288304940276 0.49444914751130464"/>
			<geometry>
				<mesh filename="textured_objs/original-3.obj"/>
			</geometry>
		</collision>
	</link>
	<joint name="joint_0" type="fixed">
		<origin xyz="0.0 0.018658453469988484 0.3295206648576805"/>
		<axis xyz="1.0 -0.0 -0.0"/>
		<child link="link_0"/>
		<parent link="link_1"/>
		<limit lower="-0.03769911184307752" upper="2.519557308179014"/>
	</joint>
	<link name="link_1">
		<visual name="lid-2">
			<origin xyz="-0.0 -0.07847442957941428 0.8239698123689851"/>
			<geometry>
				<mesh filename="textured_objs/original-5.obj"/>
			</geometry>
		</visual>
		<collision>
			<origin xyz="-0.0 -0.07847442957941428 0.8239698123689851"/>
			<geometry>
				<mesh filename="textured_objs/original-5.obj"/>
			</geometry>
		</collision>
	</link>
	<joint name="joint_1" type="revolute">
		<origin xyz="0.0 0.07847442957941428 -0.8239698123689851"/>
		<axis xyz="-1.0 -0.0 -0.0"/>
		<child link="link_1"/>
		<parent link="link_2"/>
		<limit lower="-0.050265482457436686" upper="2.142566189748239"/>
	</joint>
	<link name="link_2">
		<visual name="base_body-3">
			<origin xyz="0 0 0"/>
			<geometry>
				<mesh filename="textured_objs/original-4.obj"/>
			</geometry>
		</visual>
		<visual name="base_body-3">
			<origin xyz="0 0 0"/>
			<geometry>
				<mesh filename="textured_objs/original-1.obj"/>
			</geometry>
		</visual>
		<collision>
			<origin xyz="0 0 0"/>
			<geometry>
				<mesh filename="textured_objs/original-4.obj"/>
			</geometry>
		</collision>
		<collision>
			<origin xyz="0 0 0"/>
			<geometry>
				<mesh filename="textured_objs/original-1.obj"/>
			</geometry>
		</collision>
	</link>
	<joint name="joint_2" type="fixed">
		<origin rpy="1.570796326794897 1.57 -1.570796326794897" xyz="0 0 0"/>
		<child link="link_2"/>
		<parent link="base"/>
	</joint>
</robot>
