<?xml version="1.0" ?>
<robot name="partnet_e27e2864f9b54ca5bf9a3f8c45e44354">
	<link name="base"/>
	<link name="link_0">
		<visual name="handle-1">
			<origin xyz="-0.030375000000000263 -0.823748013051608 -0.15447603996149561"/>
			<geometry>
				<mesh filename="textured_objs/original-5.obj"/>
			</geometry>
		</visual>
		<collision>
			<origin xyz="-0.030375000000000263 -0.823748013051608 -0.15447603996149561"/>
			<geometry>
				<mesh filename="textured_objs/original-5.obj"/>
			</geometry>
		</collision>
	</link>
	<joint name="joint_0" type="revolute">
		<origin xyz="0.0244558505733485 0.823748013051608 0.1646802698159997"/>
		<axis xyz="1 0 0"/>
		<child link="link_0"/>
		<parent link="link_1"/>
		<limit lower="-0.0" upper="1.0471975511965976"/>
	</joint>
	<link name="link_1">
		<visual name="head-3">
			<origin xyz="-0.0059191494266517646 0 0.010204229854504095"/>
			<geometry>
				<mesh filename="textured_objs/original-3.obj"/>
			</geometry>
		</visual>
		<visual name="head-3">
			<origin xyz="-0.0059191494266517646 0 0.010204229854504095"/>
			<geometry>
				<mesh filename="textured_objs/original-6.obj"/>
			</geometry>
		</visual>
		<visual name="head-3">
			<origin xyz="-0.0059191494266517646 0 0.010204229854504095"/>
			<geometry>
				<mesh filename="textured_objs/original-4.obj"/>
			</geometry>
		</visual>
		<collision>
			<origin xyz="-0.0059191494266517646 0 0.010204229854504095"/>
			<geometry>
				<mesh filename="textured_objs/original-3.obj"/>
			</geometry>
		</collision>
		<collision>
			<origin xyz="-0.0059191494266517646 0 0.010204229854504095"/>
			<geometry>
				<mesh filename="textured_objs/original-6.obj"/>
			</geometry>
		</collision>
		<collision>
			<origin xyz="-0.0059191494266517646 0 0.010204229854504095"/>
			<geometry>
				<mesh filename="textured_objs/original-4.obj"/>
			</geometry>
		</collision>
	</link>
	<joint name="joint_1" type="continuous">
		<origin xyz="0.0 0 0.0"/>
		<axis xyz="0 1 0"/>
		<child link="link_1"/>
		<parent link="link_1_helper"/>
	</joint>
	<link name="link_2">
		<visual name="base_body-4">
			<origin xyz="0 0 0"/>
			<geometry>
				<mesh filename="textured_objs/original-1.obj"/>
			</geometry>
		</visual>
		<collision>
			<origin xyz="0 0 0"/>
			<geometry>
				<mesh filename="textured_objs/original-1.obj"/>
			</geometry>
		</collision>
	</link>
	<joint name="joint_2" type="fixed">
		<origin rpy="1.570796326794897 0 -1.570796326794897" xyz="0 0 0"/>
		<child link="link_2"/>
		<parent link="base"/>
	</joint>
	<link name="link_1_helper"/>
	<joint name="joint_3" type="prismatic">
		<origin xyz="0.0059191494266517646 0 -0.010204229854504095"/>
		<axis xyz="0 1 0"/>
		<child link="link_1_helper"/>
		<parent link="link_2"/>
		<limit lower="0" upper="0.10000000000000009"/>
	</joint>
</robot>
