<?xml version="1.0" ?>
<robot name="partnet_76221d93ba6f391876c18e71fd49c4dc">
	<link name="base"/>
	<link name="link_0">
		<visual name="base_body-4">
			<origin xyz="0 0 0"/>
			<geometry>
				<mesh filename="textured_objs/original-1.obj"/>
			</geometry>
		</visual>
		<collision>
			<origin xyz="0 0 0"/>
			<geometry>
				<mesh filename="textured_objs/original-1.obj"/>
			</geometry>
		</collision>
	</link>
	<joint name="joint_0" type="fixed">
		<origin rpy="1.570796326794897 0 -1.570796326794897" xyz="0 0 0"/>
		<child link="link_0"/>
		<parent link="base"/>
	</joint>
	<link name="link_1">
		<visual name="pressing_lid-2">
			<origin xyz="-0.0003029999999999977 0 0.014980500000000008"/>
			<geometry>
				<mesh filename="textured_objs/original-3.obj"/>
			</geometry>
		</visual>
		<visual name="outlier-3">
			<origin xyz="-0.0003029999999999977 0 0.014980500000000008"/>
			<geometry>
				<mesh filename="textured_objs/original-4.obj"/>
			</geometry>
		</visual>
		<collision>
			<origin xyz="-0.0003029999999999977 0 0.014980500000000008"/>
			<geometry>
				<mesh filename="textured_objs/original-3.obj"/>
			</geometry>
		</collision>
		<collision>
			<origin xyz="-0.0003029999999999977 0 0.014980500000000008"/>
			<geometry>
				<mesh filename="textured_objs/original-4.obj"/>
			</geometry>
		</collision>
	</link>
	<joint name="joint_1" type="continuous">
		<origin xyz="0.0 0 0.0"/>
		<axis xyz="0 1 0"/>
		<child link="link_1"/>
		<parent link="link_1_helper"/>
	</joint>
	<link name="link_1_helper"/>
	<joint name="joint_2" type="prismatic">
		<origin xyz="0.0003029999999999977 0 -0.014980500000000008"/>
		<axis xyz="0 -1 0"/>
		<child link="link_1_helper"/>
		<parent link="link_0"/>
		<limit lower="0" upper="0.04800000000000004"/>
	</joint>
</robot>
